<?xml version="1.0" encoding="UTF-8"?>
<!-- Generated by org.testng.reporters.JUnitReportReporter -->
<testsuite hostname="ASCDK041" name="com.pack.test.EnterPhoneNumberTest" tests="4" failures="1" timestamp="18 May 2016 07:10:17 GMT" time="80.135" errors="1">
  <testcase name="cancelRechargeTest" time="13.836" classname="com.pack.test.EnterPhoneNumberTest"/>
  <testcase name="failedTest" time="0.875" classname="com.pack.test.EnterPhoneNumberTest">
    <failure type="java.lang.AssertionError" message="expected [Payment Confirmation Awaited1] but found [Payment Confirmation Awaited]">
      <![CDATA[java.lang.AssertionError: expected [Payment Confirmation Awaited1] but found [Payment Confirmation Awaited]
	at org.testng.Assert.fail(Assert.java:94)
	at org.testng.Assert.failNotEquals(Assert.java:513)
	at org.testng.Assert.assertEqualsImpl(Assert.java:135)
	at org.testng.Assert.assertEquals(Assert.java:116)
	at org.testng.Assert.assertEquals(Assert.java:190)
	at org.testng.Assert.assertEquals(Assert.java:200)
	at com.pack.page.Recharge.getFailedMessage1(Recharge.java:265)
	at com.pack.test.EnterPhoneNumberTest.failedTest(EnterPhoneNumberTest.java:99)
	at sun.reflect.NativeMethodAccessorImpl.invoke0(Native Method)
	at sun.reflect.NativeMethodAccessorImpl.invoke(Unknown Source)
	at sun.reflect.DelegatingMethodAccessorImpl.invoke(Unknown Source)
	at java.lang.reflect.Method.invoke(Unknown Source)
	at org.testng.internal.MethodInvocationHelper.invokeMethod(MethodInvocationHelper.java:86)
	at org.testng.internal.Invoker.invokeMethod(Invoker.java:643)
	at org.testng.internal.Invoker.invokeTestMethod(Invoker.java:820)
	at org.testng.internal.Invoker.invokeTestMethods(Invoker.java:1128)
	at org.testng.internal.TestMethodWorker.invokeTestMethods(TestMethodWorker.java:129)
	at org.testng.internal.TestMethodWorker.run(TestMethodWorker.java:112)
	at java.util.concurrent.ThreadPoolExecutor.runWorker(Unknown Source)
	at java.util.concurrent.ThreadPoolExecutor$Worker.run(Unknown Source)
	at java.lang.Thread.run(Unknown Source)
]]>
    </failure>
  </testcase> <!-- failedTest -->
  <testcase name="phoneNumberText" time="65.424" classname="com.pack.test.EnterPhoneNumberTest"/>
  <testcase name="testCaseSkip" time="0.000" classname="com.pack.test.EnterPhoneNumberTest">
    <error type="org.testng.SkipException" message="Skipping this exception">
      <![CDATA[org.testng.SkipException: Skipping this exception
	at com.pack.test.EnterPhoneNumberTest.testCaseSkip(EnterPhoneNumberTest.java:107)
	at sun.reflect.NativeMethodAccessorImpl.invoke0(Native Method)
	at sun.reflect.NativeMethodAccessorImpl.invoke(Unknown Source)
	at sun.reflect.DelegatingMethodAccessorImpl.invoke(Unknown Source)
	at java.lang.reflect.Method.invoke(Unknown Source)
	at org.testng.internal.MethodInvocationHelper.invokeMethod(MethodInvocationHelper.java:86)
	at org.testng.internal.Invoker.invokeMethod(Invoker.java:643)
	at org.testng.internal.Invoker.invokeTestMethod(Invoker.java:820)
	at org.testng.internal.Invoker.invokeTestMethods(Invoker.java:1128)
	at org.testng.internal.TestMethodWorker.invokeTestMethods(TestMethodWorker.java:129)
	at org.testng.internal.TestMethodWorker.run(TestMethodWorker.java:112)
	at java.util.concurrent.ThreadPoolExecutor.runWorker(Unknown Source)
	at java.util.concurrent.ThreadPoolExecutor$Worker.run(Unknown Source)
	at java.lang.Thread.run(Unknown Source)
]]>
    </error>
  </testcase> <!-- testCaseSkip -->
</testsuite> <!-- com.pack.test.EnterPhoneNumberTest -->
